Workbook

Sheet Statement of Applicability
A1: NRW Logistics GmbH — Statement of Applicability
A2: ISO/IEC 27001:2022 Clause 6.1.3(d) — All 93 Annex A controls (ISO/IEC 27002:2022). See 'Methodology & Notes' and 'Summary Dashboard' tabs.
A4: Control ID | B4: Control Title | C4: Theme | D4: Applicable | E4: Justification | F4: Implementation Status | G4: Related Risk ID(s) | H4: Control Owner
A5: 5.1 | B5: Policies for information security | C5: Organizational | D5: Yes | E5: Foundational control; formal policy set defined in Phase 4 of this project. | F5: Planned | H5: Management
A6: 5.2 | B6: Information security roles and responsibilities | C6: Organizational | D6: Yes | E6: Roles exist informally today; to be formalized as the ISMS owner (IT Manager) and management representative. | F6: Planned | H6: Management
A7: 5.3 | B7: Segregation of duties | C7: Organizational | D7: Yes | E7: Addresses insider misuse risk in the WMS order/dispatch workflow. | F7: Planned | G7: R-006 | H7: Warehouse Ops Lead
A8: 5.4 | B8: Management responsibilities | C8: Organizational | D8: Yes | E8: Required to demonstrate leadership commitment per Clause 5. | F8: Planned | H8: Management
A9: 5.5 | B9: Contact with authorities | C9: Organizational | D9: Yes | E9: Needed for GDPR breach notification to the German data protection authority and law enforcement liaison. | F9: Planned | H9: Management
A10: 5.6 | B10: Contact with special interest groups | C10: Organizational | D10: Yes | E10: IT Manager to maintain threat-intelligence contacts (e.g. BSI, sector groups) for early warning of emerging threats. | F10: Planned | H10: IT Manager
A11: 5.7 | B11: Threat intelligence | C11: Organizational | D11: Yes | E11: Supports proactive identification of phishing campaigns and ransomware trends relevant to the sector. | F11: Planned | G11: R-001, R-002 | H11: IT Manager
A12: 5.8 | B12: Information security in project management | C12: Organizational | D12: Yes | E12: Applies to future IT projects (e.g. WMS upgrades) to ensure security is designed in, not retrofitted. | F12: Planned | H12: IT Manager
A13: 5.9 | B13: Inventory of information and other associated assets | C13: Organizational | D13: Yes | E13: Foundational to risk assessment; asset values in the risk register depend on an accurate inventory. | F13: Planned | H13: IT Manager
A14: 5.10 | B14: Acceptable use of information and other associated assets | C14: Organizational | D14: Yes | E14: Formalized in the Acceptable Use Policy produced in Phase 4. | F14: Planned | H14: Management
A15: 5.11 | B15: Return of assets | C15: Organizational | D15: Yes | E15: Relevant to device loss exposure and standard offboarding process. | F15: Planned | G15: R-005 | H15: Management
A16: 5.12 | B16: Classification of information | C16: Organizational | D16: Yes | E16: Customer shipment data and financial data require differentiated handling; classification scheme to be introduced. | F16: Planned | H16: IT Manager
A17: 5.13 | B17: Labelling of information | C17: Organizational | D17: Yes | E17: Supports the classification scheme once introduced; maturity is currently low. | F17: Planned | H17: IT Manager
A18: 5.14 | B18: Information transfer | C18: Organizational | D18: Yes | E18: Governs data exchange with the customs broker API and customer communications. | F18: Planned | G18: R-008 | H18: IT Manager
A19: 5.15 | B19: Access control | C19: Organizational | D19: Yes | E19: Core control addressing ERP access governance and admin account security. | F19: Partial | G19: R-004, R-010 | H19: IT Manager
A20: 5.16 | B20: Identity management | C20: Organizational | D20: Yes | E20: Single identity source (Active Directory) exists; lifecycle process needs formalization. | F20: Partial | H20: IT Manager
A21: 5.17 | B21: Authentication information | C21: Organizational | D21: Yes | E21: Directly addresses the weak password policy risk. | F21: Planned | G21: R-010 | H21: IT Manager
A22: 5.18 | B22: Access rights | C22: Organizational | D22: Yes | E22: Addresses the lack of periodic access review in the cloud ERP. | F22: Planned | G22: R-004 | H22: IT Manager
A23: 5.19 | B23: Information security in supplier relationships | C23: Organizational | D23: Yes | E23: Covers the Azure, telematics vendor, and customs broker relationships. | F23: Planned | G23: R-003, R-004, R-008 | H23: IT Manager
A24: 5.20 | B24: Addressing information security within supplier agreements | C24: Organizational | D24: Yes | E24: Security clauses to be incorporated into vendor contracts at renewal. | F24: Planned | H24: IT Manager
A25: 5.21 | B25: Managing information security in the ICT supply chain | C25: Organizational | D25: Yes | E25: Relevant to telematics and ERP vendor dependency. | F25: Planned | G25: R-003 | H25: IT Manager
A26: 5.22 | B26: Monitoring, review and change management of supplier services | C26: Organizational | D26: Yes | E26: Addresses irregular vendor patch cadence identified in the risk register. | F26: Planned | G26: R-003 | H26: IT Manager
A27: 5.23 | B27: Information security for use of cloud services | C27: Organizational | D27: Yes | E27: Directly addresses cloud ERP misconfiguration and DDoS exposure. | F27: Planned | G27: R-004, R-007 | H27: IT Manager
A28: 5.24 | B28: Information security incident management planning and preparation | C28: Organizational | D28: Yes | E28: No formal incident response plan exists today; required for all identified threat scenarios. | F28: Planned | H28: Management
A29: 5.25 | B29: Assessment and decision on information security events | C29: Organizational | D29: Yes | E29: Part of the incident management process to be documented. | F29: Planned | H29: IT Manager
A30: 5.26 | B30: Response to information security incidents | C30: Organizational | D30: Yes | E30: Required to respond effectively to ransomware and phishing scenarios. | F30: Planned | G30: R-001, R-002, R-009 | H30: IT Manager
A31: 5.27 | B31: Learning from information security incidents | C31: Organizational | D31: Yes | E31: Post-incident review process to feed back into risk register updates. | F31: Planned | H31: IT Manager
A32: 5.28 | B32: Collection of evidence | C32: Organizational | D32: Yes | E32: Needed to support incident investigation and potential legal or regulatory action. | F32: Planned | H32: IT Manager
A33: 5.29 | B33: Information security during disruption | C33: Organizational | D33: Yes | E33: Directly relevant to the ransomware and backup failure scenario. | F33: Planned | G33: R-009 | H33: IT Manager
A34: 5.30 | B34: ICT readiness for business continuity | C34: Organizational | D34: Yes | E34: No tested DR/BC plan exists; addresses the backup restoration gap. | F34: Planned | G34: R-002, R-009 | H34: IT Manager
A35: 5.31 | B35: Legal, statutory, regulatory and contractual requirements | C35: Organizational | D35: Yes | E35: GDPR and customer contractual obligations directly shape ISMS scope (Clause 4.2). | F35: Planned | H35: Management
A36: 5.32 | B36: Intellectual property rights | C36: Organizational | D36: Yes | E36: Covers software licensing compliance for the WMS and ERP platforms. | F36: Planned | H36: IT Manager
A37: 5.33 | B37: Protection of records | C37: Organizational | D37: Yes | E37: Applies to financial and shipment records retained in the ERP and WMS. | F37: Planned | H37: IT Manager
A38: 5.34 | B38: Privacy and protection of PII | C38: Organizational | D38: Yes | E38: Customer and employee personal data is processed; a direct GDPR obligation. | F38: Planned | H38: Management
A39: 5.35 | B39: Independent review of information security | C39: Organizational | D39: Yes | E39: Required periodically once the ISMS is operational; not yet performed. | F39: Planned (Year 2) | H39: Management
A40: 5.36 | B40: Compliance with policies, rules and standards for information security | C40: Organizational | D40: Yes | E40: Compliance monitoring to follow policy rollout in Phase 4. | F40: Planned | H40: Management
A41: 5.37 | B41: Documented operating procedures | C41: Organizational | D41: Yes | E41: Operational procedures for the WMS, backups, and incident response need documentation. | F41: Planned | H41: IT Manager
...

Sheet Summary Dashboard
A1: SoA Summary Dashboard
A3: Theme | B3: Total controls | C3: Applicable | D3: Not applicable | E3: % Applicable
A4: Organizational | B4: =COUNTIF('Statement of Applicability'!C5:C97,A4) -> 37 | C4: =COUNTIFS('Statement of Applicability'!C5:C97,A4,'Statement of Applicability'!D5:D97,"Yes") -> 37 | D4: =COUNTIFS('Statement of Applicability'!C5:C97,A4,'Statement of Applicability'!D5:D97,"No") -> 0 | E4: =C4/B4 -> 1
A5: People | B5: =COUNTIF('Statement of Applicability'!C5:C97,A5) -> 8 | C5: =COUNTIFS('Statement of Applicability'!C5:C97,A5,'Statement of Applicability'!D5:D97,"Yes") -> 8 | D5: =COUNTIFS('Statement of Applicability'!C5:C97,A5,'Statement of Applicability'!D5:D97,"No") -> 0 | E5: =C5/B5 -> 1
A6: Physical | B6: =COUNTIF('Statement of Applicability'!C5:C97,A6) -> 14 | C6: =COUNTIFS('Statement of Applicability'!C5:C97,A6,'Statement of Applicability'!D5:D97,"Yes") -> 14 | D6: =COUNTIFS('Statement of Applicability'!C5:C97,A6,'Statement of Applicability'!D5:D97,"No") -> 0 | E6: =C6/B6 -> 1
A7: Technological | B7: =COUNTIF('Statement of Applicability'!C5:C97,A7) -> 34 | C7: =COUNTIFS('Statement of Applicability'!C5:C97,A7,'Statement of Applicability'!D5:D97,"Yes") -> 24 | D7: =COUNTIFS('Statement of Applicability'!C5:C97,A7,'Statement of Applicability'!D5:D97,"No") -> 10 | E7: =C7/B7 -> 0.70588235
A8: Total | B8: =SUM(B4:B7) -> 93 | C8: =SUM(C4:C7) -> 83 | D8: =SUM(D4:D7) -> 10 | E8: =C8/B8 -> 0.89247312
A10: Implementation status breakdown
A11: Implemented | B11: =COUNTIF('Statement of Applicability'!F5:F97,A11) -> 3
A12: Partial | B12: =COUNTIF('Statement of Applicability'!F5:F97,A12) -> 9
A13: Planned | B13: =COUNTIF('Statement of Applicability'!F5:F97,A13) -> 70
A14: Planned (Year 2) | B14: =COUNTIF('Statement of Applicability'!F5:F97,A14) -> 1
A15: N/A | B15: =COUNTIF('Statement of Applicability'!F5:F97,A15) -> 10

Sheet Methodology & Notes
B1: Statement of Applicability — GRC Analyst Notes
B3: Why the SoA is the document auditors open first
B4: The Statement of Applicability is the single artifact that ties everything else together: it shows which of the 93 Annex A controls apply, why, and what the control status is. An auditor uses it as a map to decide which evidence to sample next. A weak or templated SoA — one where every justification reads 'applicable, best practice' — is the fastest way to signal that the ISMS wasn't actually built from a risk assessment.
B6: Every 'Yes' and every 'No' needs a reason, not just a checkbox
B7: Clause 6.1.3(d) explicitly requires justification for both inclusion AND exclusion. In this SoA, applicable controls are justified either by a direct link to a risk register entry (e.g. 8.13 Information backup references R-002 and R-009) or by a general governance need (e.g. 5.9 Inventory of assets). Excluded controls (the ten 'No' rows, all in the 8.2x-8.3x development-related range) are justified by a genuine absence of the underlying activity — NRW Logistics doesn't develop software, so secure coding, SDLC, and dev/test/prod separation controls don't apply.
B9: The traceability chain: risk register to SoA to policy
B10: Notice the 'Related Risk ID(s)' column. This is what separates a defensible SoA from a copy-pasted template. A control like 5.15 Access control references R-004 and R-010 directly — meaning an auditor (or you, in an interview) can walk the chain: here's the risk, here's the control selected to treat it, here's the policy or procedure that implements it. Controls without a risk reference aren't wrong — some (like 5.31 Legal requirements) are baseline governance controls every ISMS needs regardless of specific risks — but the ones that ARE risk-driven should say so.
B12: Why ten controls are marked Not Applicable, and why that's fine
B13: A SoA with 93/93 controls marked 'Yes' is a red flag, not a sign of thoroughness — it usually means no real applicability analysis was done. Here, all ten exclusions cluster around software development (8.4, 8.11, 8.25-8.31, 8.33) because NRW Logistics consumes vendor platforms (WMS, ERP, telematics) rather than building software in-house. This is a coherent, defensible pattern an auditor can verify by asking 'does this organization write code?' — a single fact that legitimately knocks out ten controls at once.
B15: Implementation status vs. applicability — two different questions
B16: Applicable = 'this control is relevant to our risk profile.' Implementation status = 'how far along are we in actually doing it.' Most controls here are marked 'Planned' rather than 'Implemented' — that's expected and honest for a first-pass ISMS build. A SoA claiming everything is already 'Implemented' on a brand-new ISMS is not credible. Auditors expect a mix, with a roadmap (see the risk register's review dates) showing how 'Planned' becomes 'Implemented' over time.
B18: How to use the Summary Dashboard tab
B19: The dashboard tab counts applicability and implementation status per theme using COUNTIF/COUNTIFS formulas that read live from the SoA sheet — edit any row in the main tab and the dashboard updates automatically. This is the kind of one-page summary a management review (Clause 9.3) would actually look at, rather than scrolling through all 93 rows.
